<?xml version="1.0" encoding="utf-8"?>
<mujoco model="crank_bot">
  <compiler angle="radian" meshdir="assets" inertiafromgeom="true" autolimits="true"/>
  <option timestep="0.002" gravity="0 0 -9.81"/>
  <asset>
    <material name="visual_black" rgba="0.0615686 0.0811765 0.0929412 1"/>
    <mesh name="base_mesh" file="base2b.stl" scale="0.001 0.001 0.001" inertia="shell"/>
    <mesh name="mg995_mesh" file="MG995.stl" scale="0.001 0.001 0.001" inertia="shell"/>
    <mesh name="mg90_mesh" file="mg90.stl" scale="0.001 0.001 0.001" inertia="shell"/>
    <mesh name="leg1_mesh" file="leg1.stl" scale="0.001 0.001 0.001" inertia="shell"/>
    <mesh name="leg2_mesh" file="leg2.stl" scale="0.001 0.001 0.001" inertia="shell"/>
  </asset>
  <worldbody>
    <body name="root" pos="0 0 0.1" euler="0 3.14159 0">
        <freejoint name="root_freejoint"/>
        <body name="base" pos="0.0 0.0 0.0">
            <geom name="base" type="mesh" mesh="base_mesh" material="visual_black" contype="0" conaffinity="0" pos="0 0 0" mass="0.05"/>
            <geom name="base_collision" type="box" size="0.04 0.09 0.005" pos="0 0 0.005" contype="1" conaffinity="1" group="3" rgba="1 0 0 0.35" mass="0.05"/>
            <!-- LEG FRONT LEFT   -->
            <body name="servo1" pos="0.015 -0.05 0.013" euler="0 -1.5708 1.5708">
                <geom name="front_left_shoulder_geom" type="mesh" mesh="mg995_mesh" material="visual_black" mass="0.055" contype="0" conaffinity="0" pos="0.0 0.0 0.02"/>
                <body name="front_left_leg" pos="-0.01 -0.0 0.0825" euler="0 3.14159 0">
                    <joint name="front_left_shoulder_joint" type="hinge" pos="0 0 0" axis="0 0 1" limited="true" range="-180 0" damping="0.15" frictionloss="0.05" armature="0.0005"/>
                    <geom name="front_left_leg_geom" type="mesh" mesh="leg1_mesh" material="visual_black" mass="0.015" contype="0" conaffinity="0" pos="0.0075 0.0 0.0"/>
                    <geom name="front_left_leg_collision" type="capsule" size="0.01 0.022" pos="0.02 0.0 0.01" euler="0 1.5708 0" contype="1" conaffinity="1" group="3" rgba="1 0 0 0.35" mass="0.005"/>
                    <body name="front_left_knee" pos="0.03 0.0 0.022" euler="0 3.14159 1.5708">    
                        <geom name="front_left_eblow_servo_geom" type="mesh" mesh="mg90_mesh" material="visual_black" mass="0.01" contype="0" conaffinity="0" pos="0.0 0.0 0.0"/>
                        <body name="front_left_lower_leg" pos="0.00 0.005 0.027" euler="0 0 0">
                            <joint name="front_left_elbow_joint" type="hinge" pos="0.0 0.0 0.0" axis="0 0 1" limited="true" range="-180 0" damping="0.08" frictionloss="0.02" armature="0.0002"/>
                            <geom name="front_left_lower_leg_geom" type="mesh" mesh="leg2_mesh" material="visual_black" mass="0.005" contype="0" conaffinity="0" pos="0.0 0.0 0.0"/>
                            <geom name="front_left_lower_leg_collision" type="capsule" size="0.0035 0.022" pos="0.0 -0.017 0.003" euler="1.5708 0 0" contype="1" conaffinity="1" group="3" rgba="1 0 0 0.35" mass="0.005"/>
                            <geom name="front_left_lower_leg_foot" type="sphere" size="0.003" pos="0.0 -0.04 0.003" contype="1" conaffinity="1" group="1" rgba="1 0 1 0.55" mass="0.0"/>
                        </body>
                    </body>
                </body>
            </body>
            <!-- LEG FRONT RIGHT   -->
            <body name="servo2" pos="-0.015 -0.05 0.013" euler="0 1.5708 1.5708">
                <geom name="front_right_shoulder_geom" type="mesh" mesh="mg995_mesh" material="visual_black" mass="0.055" contype="0" conaffinity="0" pos="0.0 0.0 0.02"/>
                <body name="front_right_leg" pos="-0.01 -0.0 0.0825" euler="0 3.14159 0">
                    <joint name="front_right_shoulder_joint" type="hinge" pos="0 0 0" axis="0 0 1" limited="true" range="0 180" damping="0.15" frictionloss="0.05" armature="0.0005"/>
                    <geom name="front_right_leg_geom" type="mesh" mesh="leg1_mesh" material="visual_black" mass="0.015" contype="0" conaffinity="0" pos="0.0075 0.0 0.0"/>
                    <geom name="front_right_leg_collision" type="capsule" size="0.01 0.022" pos="0.02 0.0 0.01" euler="0 1.5708 0" group="3" rgba="1 0 0 0.35" contype="1" conaffinity="1" mass="0.005"/>
                    
                    <body name="front_right_knee" pos="0.03 0.0 0.022" euler="0 3.14159 1.5708">    
                        <geom name="front_right_eblow_servo_geom" type="mesh" mesh="mg90_mesh" material="visual_black" mass="0.01" contype="0" conaffinity="0" pos="0.0 0.0 0.0"/>
                        
                        <body name="front_right_lower_leg" pos="0.00 0.005 0.027" euler="0 0 0">
                            <joint name="front_right_elbow_joint" type="hinge" pos="0.0 0.0 0.0" axis="0 0 1" limited="true" range="0 180" damping="0.08" frictionloss="0.02" armature="0.0002"/>
                            <geom name="front_right_lower_leg_geom" type="mesh" mesh="leg2_mesh" material="visual_black" mass="0.005" contype="0" conaffinity="0" pos="0.0 0.0 0.0"/>
                            <geom name="front_right_lower_leg_collision" type="capsule" size="0.0035 0.022" pos="0.0 -0.017 0.003" euler="1.5708 0 0" contype="1" conaffinity="1" group="3" rgba="1 0 0 0.35" mass="0.005"/>
                            <geom name="front_right_lower_leg_foot" type="sphere" size="0.003" pos="0.0 -0.04 0.003" contype="1" conaffinity="1" group="1" rgba="1 0 1 0.55" mass="0.0"/>
                        </body>
                    </body>
                </body>
            </body>
            <!-- LEG BACK LEFT   -->
             <body name="servo3" pos="0.015 0.05 0.013" euler="0 -1.5708 -1.5708">
                <geom name="back_left_shoulder_geom" type="mesh" mesh="mg995_mesh" material="visual_black" mass="0.055" contype="0" conaffinity="0" pos="0.0 0.0 0.02"/>
                <body name="back_left_leg" pos="-0.01 -0.0 0.0825" euler="0 3.14159 0">
                    <joint name="back_left_shoulder_joint" type="hinge" pos="0 0 0" axis="0 0 1" limited="true" range="0 180" damping="0.15" frictionloss="0.05" armature="0.0005"/>
                    <geom name="back_left_leg_geom" type="mesh" mesh="leg1_mesh" material="visual_black" mass="0.015" contype="0" conaffinity="0" pos="0.0075 0.0 0.0"/>
                    <geom name="back_left_leg_collision" type="capsule" size="0.01 0.022" pos="0.02 0.0 0.01" euler="0 1.5708 0" contype="1" conaffinity="1" group="3" rgba="1 0 0 0.35" mass="0.005"/>
                    
                    <body name="back_left_knee" pos="0.03 0.0 0.022" euler="0 3.14159 1.5708">    
                        <geom name="back_left_eblow_servo_geom" type="mesh" mesh="mg90_mesh" material="visual_black" mass="0.01" contype="0" conaffinity="0" pos="0.0 0.0 0.0"/>
                        <body name="back_left_lower_leg" pos="0.00 0.005 0.027" euler="0 0 0">
                            <joint name="back_left_elbow_joint" type="hinge" pos="0.0 0.0 0.0" axis="0 0 1" limited="true" range="-180 0" damping="0.08" frictionloss="0.02" armature="0.0002"/>
                            <geom name="back_left_lower_leg_geom" type="mesh" mesh="leg2_mesh" material="visual_black" mass="0.005" contype="0" conaffinity="0" pos="0.0 0.0 0.0"/>
                            <geom name="back_left_lower_leg_collision" type="capsule" size="0.0035 0.022" pos="0.0 -0.017 0.003" euler="1.5708 0 0" contype="1" conaffinity="1" group="3" rgba="1 0 0 0.35" mass="0.005"/>
                            <geom name="back_left_lower_leg_foot" type="sphere" size="0.003" pos="0.0 -0.04 0.003" contype="1" conaffinity="1" group="1" rgba="1 0 1 0.55" mass="0.0"/>
                        </body>
                    </body>
                </body>
            </body>
            <!-- LEG BACK RIGHT   -->
            <body name="servo4" pos="-0.015 0.05 0.013" euler="0 1.5708 -1.5708">
                <geom name="back_right_shoulder_geom" type="mesh" mesh="mg995_mesh" material="visual_black" mass="0.055" contype="0" conaffinity="0" pos="0.0 0.0 0.02"/>
                <body name="back_right_leg" pos="-0.01 -0.0 0.0825" euler="0 3.14159 0">
                    <joint name="back_right_shoulder_joint" type="hinge" pos="0 0 0" axis="0 0 1" limited="true" range="-180 0" damping="0.15" frictionloss="0.05" armature="0.0005"/>
                    <geom name="back_right_leg_geom" type="mesh" mesh="leg1_mesh" material="visual_black" mass="0.015" contype="0" conaffinity="0" pos="0.0075 0.0 0.0"/>
                    <geom name="back_right_leg_collision" type="capsule" size="0.01 0.022" pos="0.02 0.0 0.01" euler="0 1.5708 0" contype="1" conaffinity="1" group="3" rgba="1 0 0 0.35" mass="0.005"/>
                    
                    <body name="back_right_knee" pos="0.03 0.0 0.022" euler="0 3.14159 1.5708">    
                        <geom name="back_right_eblow_servo_geom" type="mesh" mesh="mg90_mesh" material="visual_black" mass="0.01" contype="0" conaffinity="0" pos="0 0 0"/>
                        <body name="back_right_lower_leg" pos="0.00 0.005 0.027" euler="0 0 0">
                            <joint name="back_right_elbow_joint" type="hinge" pos="0.0 0.0 0.0" axis="0 0 1" limited="true" range="0 180" damping="0.08" frictionloss="0.02" armature="0.0002"/>
                            <geom name="back_right_lower_leg_geom" type="mesh" mesh="leg2_mesh" material="visual_black" mass="0.005" contype="0" conaffinity="0" pos="0.0 0.0 0.0"/>
                            <geom name="back_right_lower_leg_collision" type="capsule" size="0.0035 0.022" pos="0.0 -0.017 0.003" euler="1.5708 0 0" contype="1" conaffinity="1" group="3" rgba="1 0 0 0.35" mass="0.005"/>
                            <geom name="back_right_lower_leg_foot" type="sphere" size="0.003" pos="0.0 -0.04 0.003" contype="1" conaffinity="1" group="1" rgba="1 0 1 0.55" mass="0.0"/>
                        </body>
                    </body>
                </body>
            </body>
        </body>
    </body>
</worldbody>

<contact>
    <exclude body1="servo1" body2="front_left_leg"/>
    <exclude body1="front_left_leg" body2="front_left_knee"/>
    <exclude body1="front_left_knee" body2="front_left_lower_leg"/>
    <exclude body1="servo2" body2="front_right_leg"/>
    <exclude body1="front_right_leg" body2="front_right_knee"/>
    <exclude body1="front_right_knee" body2="front_right_lower_leg"/>
    <exclude body1="servo3" body2="back_left_leg"/>
    <exclude body1="back_left_leg" body2="back_left_knee"/>
    <exclude body1="back_left_knee" body2="back_left_lower_leg"/>
    <exclude body1="servo4" body2="back_right_leg"/>
    <exclude body1="back_right_leg" body2="back_right_knee"/>
    <exclude body1="back_right_knee" body2="back_right_lower_leg"/>
</contact>

<actuator>
    <position name="front_left_shoulder_pos" joint="front_left_shoulder_joint" kp="8" kv="0.4" ctrlrange="-3.14159 0.0" forcerange="-1.2 1.2"/>
    <position name="front_left_elbow_pos" joint="front_left_elbow_joint" kp="3" kv="0.15" ctrlrange="-3.14159 0.0" forcerange="-0.25 0.25"/>
    <position name="front_right_shoulder_pos" joint="front_right_shoulder_joint" kp="8" kv="0.4" ctrlrange="0.0 3.14159" forcerange="-1.2 1.2"/>
    <position name="front_right_elbow_pos" joint="front_right_elbow_joint" kp="3" kv="0.15" ctrlrange="0.0 3.14159" forcerange="-0.25 0.25"/>
    <position name="back_left_shoulder_pos" joint="back_left_shoulder_joint" kp="8" kv="0.4" ctrlrange="0.0 3.14159" forcerange="-1.2 1.2"/>
    <position name="back_left_elbow_pos" joint="back_left_elbow_joint" kp="3" kv="0.15" ctrlrange="-3.14159 0.0" forcerange="-0.25 0.25"/>
    <position name="back_right_shoulder_pos" joint="back_right_shoulder_joint" kp="8" kv="0.4" ctrlrange="-3.14159 0.0" forcerange="-1.2 1.2"/>
    <position name="back_right_elbow_pos" joint="back_right_elbow_joint" kp="3" kv="0.15" ctrlrange="0.0 3.14159" forcerange="-0.25 0.25"/>
</actuator>

</mujoco>
